<sdf version='1.6'>
  <model name='jackal'>
    <link name='base_link'>
      <pose frame=''>0 0 0 0 -0 0</pose>
      <inertial>
        <pose frame=''>0.01874 0.001875 0.083599 0 -0 0</pose>
        <mass>17.624</mass>
        <inertia>
          <ixx>0.389656</ixx>
          <ixy>-0.000577266</ixy>
          <ixz>-0.0132299</ixz>
          <iyy>0.480339</iyy>
          <iyz>-0.000351484</iyz>
          <izz>0.462498</izz>
        </inertia>
      </inertial>
      <collision name='base_link_fixed_joint_lump__chassis_link_collision'>
        <pose frame=''>0 0 0.092 0 -0 0</pose>
        <geometry>
          <box>
            <size>0.42 0.31 0.184</size>
          </box>
        </geometry>
        <surface>
          <contact>
            <ode/>
          </contact>
          <friction>
            <ode/>
          </friction>
        </surface>
      </collision>
      <collision name='base_link_fixed_joint_lump__front_laser_collision_1'>
        <pose frame=''>0.12 0 0.283 0 -0 0</pose>
        <geometry>
          <box>
            <size>0.105 0.1 0.1</size>
          </box>
        </geometry>
        <surface>
          <contact>
            <ode/>
          </contact>
          <friction>
            <ode/>
          </friction>
        </surface>
      </collision>
      <visual name='base_link_fixed_joint_lump__chassis_link_visual'>
        <pose frame=''>0 0 -0.0655 1.5708 -0 1.5708</pose>
        <geometry>
          <mesh>
            <scale>1 1 1</scale>
            <uri>model://jackal_description/meshes/jackal-base.stl</uri>
          </mesh>
        </geometry>
        <material>
          <script>
            <name>Gazebo/DarkGrey</name>
            <uri>file://media/materials/scripts/gazebo.material</uri>
          </script>
        </material>
      </visual>
      <visual name='base_link_fixed_joint_lump__front_fender_link_visual_1'>
        <pose frame=''>0 0 0 0 -0 0</pose>
        <geometry>
          <mesh>
            <scale>1 1 1</scale>
            <uri>model://jackal_description/meshes/jackal-fender.stl</uri>
          </mesh>
        </geometry>
        <material>
          <script>
            <name>Gazebo/Yellow</name>
            <uri>file://media/materials/scripts/gazebo.material</uri>
          </script>
        </material>
      </visual>
      <visual name='base_link_fixed_joint_lump__front_laser_mount_visual_2'>
        <pose frame=''>0.12 0 0.184 0 -0 0</pose>
        <geometry>
          <mesh>
            <scale>1 1 1</scale>
            <uri>model://jackal_description/meshes/sick-lms1xx-bracket.stl</uri>
          </mesh>
        </geometry>
        <material>
          <script>
            <name>Gazebo/DarkGrey</name>
            <uri>file://media/materials/scripts/gazebo.material</uri>
          </script>
        </material>
      </visual>
      <visual name='base_link_fixed_joint_lump__front_laser_visual_3'>
        <pose frame=''>0.12 0 0.333 0 -0 0</pose>
        <geometry>
          <mesh>
            <scale>1 1 1</scale>
            <uri>model://lms1xx/meshes/sick-lms1xx.dae</uri>
          </mesh>
        </geometry>
        <material>
          <script>
            <uri>__default__</uri>
            <name>__default__</name>
          </script>
        </material>
      </visual>
      <visual name='base_link_fixed_joint_lump__navsat_link_visual_4'>
        <pose frame=''>-0.18 0.126 0.1895 0 -0 0</pose>
        <geometry>
          <cylinder>
            <length>0.016</length>
            <radius>0.026</radius>
          </cylinder>
        </geometry>
        <material>
          <script>
            <name>Gazebo/DarkGrey</name>
            <uri>file://media/materials/scripts/gazebo.material</uri>
          </script>
        </material>
      </visual>
      <visual name='base_link_fixed_joint_lump__rear_fender_link_visual_5'>
        <pose frame=''>0 0 0 0 -0 -3.14159</pose>
        <geometry>
          <mesh>
            <scale>1 1 1</scale>
            <uri>model://jackal_description/meshes/jackal-fender.stl</uri>
          </mesh>
        </geometry>
        <material>
          <script>
            <name>Gazebo/Yellow</name>
            <uri>file://media/materials/scripts/gazebo.material</uri>
          </script>
        </material>
      </visual>
      <velocity_decay/>
      <velocity_decay/>
      <velocity_decay/>
      <velocity_decay/>
      <velocity_decay/>
      <velocity_decay/>
      <sensor name='front_laser' type='gpu_ray'>
        <visualize>0</visualize>
        <update_rate>50</update_rate>
        <ray>
          <scan>
            <horizontal>
              <samples>720</samples>
              <resolution>1</resolution>
              <min_angle>-2.35619</min_angle>
              <max_angle>2.35619</max_angle>
            </horizontal>
          </scan>
          <range>
            <min>0.1</min>
            <max>30</max>
            <resolution>0.01</resolution>
          </range>
          <noise>
            <type>gaussian</type>
            <mean>0</mean>
            <stddev>0.001</stddev>
          </noise>
        </ray>
        <plugin name='gazebo_ros_laser' filename='libgazebo_ros_gpu_laser.so'>
          <topicName>front/scan</topicName>
          <frameName>front_laser</frameName>
          <robotNamespace>/</robotNamespace>
        </plugin>
        <pose frame=''>0.12 0 0.333 0 -0 0</pose>
      </sensor>
      <velocity_decay/>
      <gravity>1</gravity>
      <velocity_decay/>
    </link>
    <link name='front_left_wheel_link'>
      <pose frame=''>0.131 0.187795 0.0345 0 -0 0</pose>
      <inertial>
        <pose frame=''>0 0 0 0 -0 0</pose>
        <mass>0.477</mass>
        <inertia>
          <ixx>0.0013</ixx>
          <ixy>0</ixy>
          <ixz>0</ixz>
          <iyy>0.0024</iyy>
          <iyz>0</iyz>
          <izz>0.0013</izz>
        </inertia>
      </inertial>
      <collision name='front_left_wheel_link_collision'>
        <pose frame=''>0 0 0 1.5708 -0 0</pose>
        <geometry>
          <cylinder>
            <length>0.04</length>
            <radius>0.098</radius>
          </cylinder>
        </geometry>
        <surface>
          <contact>
            <ode>
              <kp>1e+07</kp>
              <kd>1</kd>
            </ode>
          </contact>
          <friction>
            <ode>
              <mu>0.5</mu>
              <mu2>0.5</mu2>
              <fdir1>1 0 0</fdir1>
            </ode>
          </friction>
        </surface>
      </collision>
      <visual name='front_left_wheel_link_visual'>
        <pose frame=''>0 0 0 1.5708 -0 0</pose>
        <geometry>
          <mesh>
            <scale>1 1 1</scale>
            <uri>model://jackal_description/meshes/jackal-wheel.stl</uri>
          </mesh>
        </geometry>
        <material>
          <script>
            <name>Gazebo/DarkGrey</name>
            <uri>file://media/materials/scripts/gazebo.material</uri>
          </script>
        </material>
      </visual>
      <gravity>1</gravity>
      <velocity_decay/>
      <self_collide>0</self_collide>
    </link>
    <joint name='front_left_wheel' type='revolute'>
      <child>front_left_wheel_link</child>
      <parent>base_link</parent>
      <axis>
        <xyz>0 1 0</xyz>
        <limit>
          <lower>-1e+16</lower>
          <upper>1e+16</upper>
        </limit>
        <dynamics>
          <spring_reference>0</spring_reference>
          <spring_stiffness>0</spring_stiffness>
        </dynamics>
        <use_parent_model_frame>1</use_parent_model_frame>
      </axis>
    </joint>
    <link name='front_right_wheel_link'>
      <pose frame=''>0.131 -0.187795 0.0345 0 -0 0</pose>
      <inertial>
        <pose frame=''>0 0 0 0 -0 0</pose>
        <mass>0.477</mass>
        <inertia>
          <ixx>0.0013</ixx>
          <ixy>0</ixy>
          <ixz>0</ixz>
          <iyy>0.0024</iyy>
          <iyz>0</iyz>
          <izz>0.0013</izz>
        </inertia>
      </inertial>
      <collision name='front_right_wheel_link_collision'>
        <pose frame=''>0 0 0 1.5708 -0 0</pose>
        <geometry>
          <cylinder>
            <length>0.04</length>
            <radius>0.098</radius>
          </cylinder>
        </geometry>
        <surface>
          <contact>
            <ode>
              <kp>1e+07</kp>
              <kd>1</kd>
            </ode>
          </contact>
          <friction>
            <ode>
              <mu>0.5</mu>
              <mu2>0.5</mu2>
              <fdir1>1 0 0</fdir1>
            </ode>
          </friction>
        </surface>
      </collision>
      <visual name='front_right_wheel_link_visual'>
        <pose frame=''>0 0 0 1.5708 -0 0</pose>
        <geometry>
          <mesh>
            <scale>1 1 1</scale>
            <uri>model://jackal_description/meshes/jackal-wheel.stl</uri>
          </mesh>
        </geometry>
        <material>
          <script>
            <name>Gazebo/DarkGrey</name>
            <uri>file://media/materials/scripts/gazebo.material</uri>
          </script>
        </material>
      </visual>
      <gravity>1</gravity>
      <velocity_decay/>
      <self_collide>0</self_collide>
    </link>
    <joint name='front_right_wheel' type='revolute'>
      <child>front_right_wheel_link</child>
      <parent>base_link</parent>
      <axis>
        <xyz>0 1 0</xyz>
        <limit>
          <lower>-1e+16</lower>
          <upper>1e+16</upper>
        </limit>
        <dynamics>
          <spring_reference>0</spring_reference>
          <spring_stiffness>0</spring_stiffness>
        </dynamics>
        <use_parent_model_frame>1</use_parent_model_frame>
      </axis>
    </joint>
    <link name='rear_left_wheel_link'>
      <pose frame=''>-0.131 0.187795 0.0345 0 -0 0</pose>
      <inertial>
        <pose frame=''>0 0 0 0 -0 0</pose>
        <mass>0.477</mass>
        <inertia>
          <ixx>0.0013</ixx>
          <ixy>0</ixy>
          <ixz>0</ixz>
          <iyy>0.0024</iyy>
          <iyz>0</iyz>
          <izz>0.0013</izz>
        </inertia>
      </inertial>
      <collision name='rear_left_wheel_link_collision'>
        <pose frame=''>0 0 0 1.5708 -0 0</pose>
        <geometry>
          <cylinder>
            <length>0.04</length>
            <radius>0.098</radius>
          </cylinder>
        </geometry>
        <surface>
          <contact>
            <ode>
              <kp>1e+07</kp>
              <kd>1</kd>
            </ode>
          </contact>
          <friction>
            <ode>
              <mu>0.5</mu>
              <mu2>0.5</mu2>
              <fdir1>1 0 0</fdir1>
            </ode>
          </friction>
        </surface>
      </collision>
      <visual name='rear_left_wheel_link_visual'>
        <pose frame=''>0 0 0 1.5708 -0 0</pose>
        <geometry>
          <mesh>
            <scale>1 1 1</scale>
            <uri>model://jackal_description/meshes/jackal-wheel.stl</uri>
          </mesh>
        </geometry>
        <material>
          <script>
            <name>Gazebo/DarkGrey</name>
            <uri>file://media/materials/scripts/gazebo.material</uri>
          </script>
        </material>
      </visual>
      <gravity>1</gravity>
      <velocity_decay/>
      <self_collide>0</self_collide>
    </link>
    <joint name='rear_left_wheel' type='revolute'>
      <child>rear_left_wheel_link</child>
      <parent>base_link</parent>
      <axis>
        <xyz>0 1 0</xyz>
        <limit>
          <lower>-1e+16</lower>
          <upper>1e+16</upper>
        </limit>
        <dynamics>
          <spring_reference>0</spring_reference>
          <spring_stiffness>0</spring_stiffness>
        </dynamics>
        <use_parent_model_frame>1</use_parent_model_frame>
      </axis>
    </joint>
    <link name='rear_right_wheel_link'>
      <pose frame=''>-0.131 -0.187795 0.0345 0 -0 0</pose>
      <inertial>
        <pose frame=''>0 0 0 0 -0 0</pose>
        <mass>0.477</mass>
        <inertia>
          <ixx>0.0013</ixx>
          <ixy>0</ixy>
          <ixz>0</ixz>
          <iyy>0.0024</iyy>
          <iyz>0</iyz>
          <izz>0.0013</izz>
        </inertia>
      </inertial>
      <collision name='rear_right_wheel_link_collision'>
        <pose frame=''>0 0 0 1.5708 -0 0</pose>
        <geometry>
          <cylinder>
            <length>0.04</length>
            <radius>0.098</radius>
          </cylinder>
        </geometry>
        <surface>
          <contact>
            <ode>
              <kp>1e+07</kp>
              <kd>1</kd>
            </ode>
          </contact>
          <friction>
            <ode>
              <mu>0.5</mu>
              <mu2>0.5</mu2>
              <fdir1>1 0 0</fdir1>
            </ode>
          </friction>
        </surface>
      </collision>
      <visual name='rear_right_wheel_link_visual'>
        <pose frame=''>0 0 0 1.5708 -0 0</pose>
        <geometry>
          <mesh>
            <scale>1 1 1</scale>
            <uri>model://jackal_description/meshes/jackal-wheel.stl</uri>
          </mesh>
        </geometry>
        <material>
          <script>
            <name>Gazebo/DarkGrey</name>
            <uri>file://media/materials/scripts/gazebo.material</uri>
          </script>
        </material>
      </visual>
      <gravity>1</gravity>
      <velocity_decay/>
      <self_collide>0</self_collide>
    </link>
    <joint name='rear_right_wheel' type='revolute'>
      <child>rear_right_wheel_link</child>
      <parent>base_link</parent>
      <axis>
        <xyz>0 1 0</xyz>
        <limit>
          <lower>-1e+16</lower>
          <upper>1e+16</upper>
        </limit>
        <dynamics>
          <spring_reference>0</spring_reference>
          <spring_stiffness>0</spring_stiffness>
        </dynamics>
        <use_parent_model_frame>1</use_parent_model_frame>
      </axis>
    </joint>
    <plugin name='gazebo_ros_control' filename='libgazebo_ros_control.so'>
      <robotNamespace>/</robotNamespace>
    </plugin>
    <plugin name='imu_controller' filename='libhector_gazebo_ros_imu.so'>
      <robotNamespace>/</robotNamespace>
      <updateRate>50.0</updateRate>
      <topicName>imu/data</topicName>
      <accelDrift>0.005 0.005 0.005</accelDrift>
      <accelGaussianNoise>0.005 0.005 0.005</accelGaussianNoise>
      <rateDrift>0.005 0.005 0.005</rateDrift>
      <rateGaussianNoise>0.005 0.005 0.005</rateGaussianNoise>
      <headingDrift>0.005</headingDrift>
      <headingGaussianNoise>0.005</headingGaussianNoise>
      <bodyName>base_link</bodyName>
      <xyzOffset>0 0 0</xyzOffset>
      <rpyOffset>0 -0 0</rpyOffset>
    </plugin>
    <static>0</static>
    <plugin name='gps_controller' filename='libhector_gazebo_ros_gps.so'>
      <updateRate>40</updateRate>
      <robotNamespace>/</robotNamespace>
      <frameId>base_link</frameId>
      <topicName>/navsat/fix</topicName>
      <velocityTopicName>/navsat/vel</velocityTopicName>
      <referenceLatitude>49.9</referenceLatitude>
      <referenceLongitude>8.9</referenceLongitude>
      <referenceHeading>0</referenceHeading>
      <referenceAltitude>0</referenceAltitude>
      <drift>0.0001 0.0001 0.0001</drift>
      <bodyName>base_link</bodyName>
      <xyzOffset>0.18 -0.126 -0.1815</xyzOffset>
      <rpyOffset>0 -0 0</rpyOffset>
    </plugin>
  </model>
</sdf>
